/home/oseloka/pyprojects/maplecourt_py/MapleCourt_propertyMgt/src/notifications
--- Logging error ---
Traceback (most recent call last):
  File "/usr/lib/python3.10/logging/__init__.py", line 1104, in emit
    self.flush()
TypeError: 'bool' object is not callable
Call stack:
  File "/home/oseloka/pyprojects/maplecourt_py/MapleCourt_propertyMgt/src/notifications/rent_notice_email.py", line 12, in <module>
    logger = mc_logger(log_name='rent_notice_log', log_level='INFO', log_file='rent_notice.log')
  File "/home/oseloka/pyprojects/maplecourt_py/MapleCourt_propertyMgt/src/utils/my_logging.py", line 39, in mc_logger
    config = read_config()
  File "/home/oseloka/pyprojects/maplecourt_py/MapleCourt_propertyMgt/src/utils/file_paths.py", line 67, in read_config
    logger_instance.info("Read mc_config.ini successful")
Message: 'Read mc_config.ini successful'
Arguments: ()
2023-12-26 11:45:02,469 - read_config_log - INFO - Read mc_config.ini successful
--- Logging error ---
Traceback (most recent call last):
  File "/usr/lib/python3.10/logging/__init__.py", line 1104, in emit
    self.flush()
TypeError: 'bool' object is not callable
Call stack:
  File "/home/oseloka/pyprojects/maplecourt_py/MapleCourt_propertyMgt/src/notifications/rent_notice_email.py", line 121, in <module>
    logger.info(f"PROCESS RUN TIMESTAMP...........................................................................: {datetime.now()}\n")
Message: 'PROCESS RUN TIMESTAMP...........................................................................: 2023-12-26 11:45:02.470143\n'
Arguments: ()
2023-12-26 11:45:02,470 - rent_notice_log - INFO - PROCESS RUN TIMESTAMP...........................................................................: 2023-12-26 11:45:02.470143

--- Logging error ---
Traceback (most recent call last):
  File "/usr/lib/python3.10/logging/__init__.py", line 1104, in emit
    self.flush()
TypeError: 'bool' object is not callable
Call stack:
  File "/home/oseloka/pyprojects/maplecourt_py/MapleCourt_propertyMgt/src/notifications/rent_notice_email.py", line 123, in <module>
    send_upcoming_rent_email(logger)
  File "/home/oseloka/pyprojects/maplecourt_py/MapleCourt_propertyMgt/src/notifications/rent_notice_email.py", line 77, in send_upcoming_rent_email
    pool = pool_connection(logger_instance)
  File "/home/oseloka/pyprojects/maplecourt_py/MapleCourt_propertyMgt/src/utils/credentials.py", line 100, in pool_connection
    start_mysql_service(sudopass, logger_instance)
  File "/home/oseloka/pyprojects/maplecourt_py/MapleCourt_propertyMgt/src/utils/credentials.py", line 82, in start_mysql_service
    logger_instance.info(f"MySQL process is already running.")
Message: 'MySQL process is already running.'
Arguments: ()
2023-12-26 11:45:02,472 - rent_notice_log - INFO - MySQL process is already running.
--- Logging error ---
Traceback (most recent call last):
  File "/usr/lib/python3.10/logging/__init__.py", line 1104, in emit
    self.flush()
TypeError: 'bool' object is not callable
Call stack:
  File "/home/oseloka/pyprojects/maplecourt_py/MapleCourt_propertyMgt/src/notifications/rent_notice_email.py", line 123, in <module>
    send_upcoming_rent_email(logger)
  File "/home/oseloka/pyprojects/maplecourt_py/MapleCourt_propertyMgt/src/notifications/rent_notice_email.py", line 77, in send_upcoming_rent_email
    pool = pool_connection(logger_instance)
  File "/home/oseloka/pyprojects/maplecourt_py/MapleCourt_propertyMgt/src/utils/credentials.py", line 111, in pool_connection
    logger_instance.info(f"MySQL connection pool created.")
Message: 'MySQL connection pool created.'
Arguments: ()
2023-12-26 11:45:02,614 - rent_notice_log - INFO - MySQL connection pool created.
--- Logging error ---
Traceback (most recent call last):
  File "/usr/lib/python3.10/logging/__init__.py", line 1104, in emit
    self.flush()
TypeError: 'bool' object is not callable
Call stack:
  File "/home/oseloka/pyprojects/maplecourt_py/MapleCourt_propertyMgt/src/notifications/rent_notice_email.py", line 123, in <module>
    send_upcoming_rent_email(logger)
  File "/home/oseloka/pyprojects/maplecourt_py/MapleCourt_propertyMgt/src/notifications/rent_notice_email.py", line 78, in send_upcoming_rent_email
    connection, cursor = get_cursor(pool, logger_instance)
  File "/home/oseloka/pyprojects/maplecourt_py/MapleCourt_propertyMgt/src/utils/credentials.py", line 127, in get_cursor
    logger_instance.info(f"Connected to {pool.pool_name} pool successfully\n")
Message: 'Connected to mc_pool pool successfully\n'
Arguments: ()
2023-12-26 11:45:02,615 - rent_notice_log - INFO - Connected to mc_pool pool successfully

--- Logging error ---
Traceback (most recent call last):
  File "/usr/lib/python3.10/logging/__init__.py", line 1104, in emit
    self.flush()
TypeError: 'bool' object is not callable
Call stack:
  File "/home/oseloka/pyprojects/maplecourt_py/MapleCourt_propertyMgt/src/notifications/rent_notice_email.py", line 123, in <module>
    send_upcoming_rent_email(logger)
  File "/home/oseloka/pyprojects/maplecourt_py/MapleCourt_propertyMgt/src/notifications/rent_notice_email.py", line 80, in send_upcoming_rent_email
    config = read_config(logger_instance)
  File "/home/oseloka/pyprojects/maplecourt_py/MapleCourt_propertyMgt/src/utils/file_paths.py", line 67, in read_config
    logger_instance.info("Read mc_config.ini successful")
Message: 'Read mc_config.ini successful'
Arguments: ()
2023-12-26 11:45:02,616 - rent_notice_log - INFO - Read mc_config.ini successful
--- Logging error ---
Traceback (most recent call last):
  File "/usr/lib/python3.10/logging/__init__.py", line 1104, in emit
    self.flush()
TypeError: 'bool' object is not callable
Call stack:
  File "/home/oseloka/pyprojects/maplecourt_py/MapleCourt_propertyMgt/src/notifications/rent_notice_email.py", line 123, in <module>
    send_upcoming_rent_email(logger)
  File "/home/oseloka/pyprojects/maplecourt_py/MapleCourt_propertyMgt/src/notifications/rent_notice_email.py", line 83, in send_upcoming_rent_email
    logger_instance.info("Checking for upcoming rent...")
Message: 'Checking for upcoming rent...'
Arguments: ()
2023-12-26 11:45:02,616 - rent_notice_log - INFO - Checking for upcoming rent...
--- Logging error ---
Traceback (most recent call last):
  File "/usr/lib/python3.10/logging/__init__.py", line 1104, in emit
    self.flush()
TypeError: 'bool' object is not callable
Call stack:
  File "/home/oseloka/pyprojects/maplecourt_py/MapleCourt_propertyMgt/src/notifications/rent_notice_email.py", line 123, in <module>
    send_upcoming_rent_email(logger)
  File "/home/oseloka/pyprojects/maplecourt_py/MapleCourt_propertyMgt/src/notifications/rent_notice_email.py", line 105, in send_upcoming_rent_email
    logger_instance.info("No upcoming rent found.")
Message: 'No upcoming rent found.'
Arguments: ()
2023-12-26 11:45:02,617 - rent_notice_log - INFO - No upcoming rent found.
--- Logging error ---
Traceback (most recent call last):
  File "/usr/lib/python3.10/logging/__init__.py", line 1104, in emit
    self.flush()
TypeError: 'bool' object is not callable
Call stack:
  File "/home/oseloka/pyprojects/maplecourt_py/MapleCourt_propertyMgt/src/notifications/rent_notice_email.py", line 123, in <module>
    send_upcoming_rent_email(logger)
  File "/home/oseloka/pyprojects/maplecourt_py/MapleCourt_propertyMgt/src/notifications/rent_notice_email.py", line 116, in send_upcoming_rent_email
    logger_instance.info("Connection and cursor closed.\n")
Message: 'Connection and cursor closed.\n'
Arguments: ()
2023-12-26 11:45:02,619 - rent_notice_log - INFO - Connection and cursor closed.

Exception ignored in atexit callback: <function shutdown at 0x7f9784ad8b80>
Traceback (most recent call last):
  File "/usr/lib/python3.10/logging/__init__.py", line 2182, in shutdown
    h.flush()
TypeError: 'bool' object is not callable
/home/oseloka/pyprojects/maplecourt_py/MapleCourt_propertyMgt/src/notifications
2023-12-27 11:45:01,763 - src.utils.file_paths - INFO - Read mc_config.ini successful
2023-12-27 11:45:01,763 - rent_notice_log - INFO - PROCESS RUN TIMESTAMP...........................................................................: 2023-12-27 11:45:01.763448

2023-12-27 11:45:01,765 - rent_notice_log - INFO - MySQL process is already running.
2023-12-27 11:45:01,920 - rent_notice_log - INFO - MySQL connection pool created.
2023-12-27 11:45:01,921 - rent_notice_log - INFO - Connected to mc_pool pool successfully

2023-12-27 11:45:01,923 - rent_notice_log - INFO - Read mc_config.ini successful
2023-12-27 11:45:01,924 - rent_notice_log - INFO - Checking for upcoming rent...
2023-12-27 11:45:01,925 - rent_notice_log - INFO - No upcoming rent found.
2023-12-27 11:45:01,925 - rent_notice_log - INFO - Connection and cursor closed.

/home/oseloka/pyprojects/maplecourt_py/MapleCourt_propertyMgt/src/notifications
2023-12-29 11:45:01,782 - src.utils.file_paths - INFO - Read mc_config.ini successful
2023-12-29 11:45:01,783 - rent_notice_log - INFO - PROCESS RUN TIMESTAMP...........................................................................: 2023-12-29 11:45:01.783130

2023-12-29 11:45:01,785 - rent_notice_log - INFO - MySQL process is already running.
2023-12-29 11:45:01,942 - rent_notice_log - INFO - MySQL connection pool created.
2023-12-29 11:45:01,943 - rent_notice_log - INFO - Connected to mc_pool pool successfully

2023-12-29 11:45:01,943 - rent_notice_log - INFO - Read mc_config.ini successful
2023-12-29 11:45:01,943 - rent_notice_log - INFO - Checking for upcoming rent...
2023-12-29 11:45:01,944 - rent_notice_log - INFO - No upcoming rent found.
2023-12-29 11:45:01,946 - rent_notice_log - INFO - Connection and cursor closed.

/home/oseloka/pyprojects/maplecourt_py/MapleCourt_propertyMgt/src/notifications
2023-12-31 11:45:01,645 - src.utils.file_paths - INFO - Read mc_config.ini successful
2023-12-31 11:45:01,646 - rent_notice_log - INFO - PROCESS RUN TIMESTAMP...........................................................................: 2023-12-31 11:45:01.646290

2023-12-31 11:45:01,647 - rent_notice_log - INFO - MySQL process is already running.
2023-12-31 11:45:01,813 - rent_notice_log - INFO - MySQL connection pool created.
2023-12-31 11:45:01,814 - rent_notice_log - INFO - Connected to mc_pool pool successfully

2023-12-31 11:45:01,815 - rent_notice_log - INFO - Read mc_config.ini successful
2023-12-31 11:45:01,815 - rent_notice_log - INFO - Checking for upcoming rent...
2023-12-31 11:45:01,816 - rent_notice_log - INFO - No upcoming rent found.
2023-12-31 11:45:01,817 - rent_notice_log - INFO - Connection and cursor closed.

/home/oseloka/pyprojects/maplecourt_py/MapleCourt_propertyMgt/src/notifications
2024-01-01 11:45:01,543 - src.utils.file_paths - INFO - Read mc_config.ini successful
2024-01-01 11:45:01,544 - rent_notice_log - INFO - PROCESS RUN TIMESTAMP...........................................................................: 2024-01-01 11:45:01.543981

2024-01-01 11:45:01,545 - rent_notice_log - INFO - MySQL process is already running.
2024-01-01 11:45:01,680 - rent_notice_log - INFO - MySQL connection pool created.
2024-01-01 11:45:01,681 - rent_notice_log - INFO - Connected to mc_pool pool successfully

2024-01-01 11:45:01,681 - rent_notice_log - INFO - Read mc_config.ini successful
2024-01-01 11:45:01,681 - rent_notice_log - INFO - Checking for upcoming rent...
2024-01-01 11:45:01,682 - rent_notice_log - INFO - Upcoming rent data found.

2024-01-01 11:45:01,682 - rent_notice_log - ERROR - An error occured
Traceback (most recent call last):
  File "/home/oseloka/pyprojects/maplecourt_py/MapleCourt_propertyMgt/src/notifications/rent_notice_email.py", line 90, in send_upcoming_rent_email
    tenant_name, email, rent_amount, service_charge, due_date, payment_total = record[:5]
ValueError: not enough values to unpack (expected 6, got 5)
2024-01-01 11:45:01,684 - rent_notice_log - INFO - Connection and cursor closed.

/home/oseloka/pyprojects/maplecourt_py/MapleCourt_propertyMgt/src/notifications
/home/oseloka/pyprojects/maplecourt_py/MapleCourt_propertyMgt/src/notifications
/home/oseloka/pyprojects/maplecourt_py/MapleCourt_propertyMgt/src/notifications
/home/oseloka/pyprojects/maplecourt_py/MapleCourt_propertyMgt/src/notifications
/home/oseloka/pyprojects/maplecourt_py/MapleCourt_propertyMgt/src/notifications
/home/oseloka/pyprojects/maplecourt_py/MapleCourt_propertyMgt/src/notifications
/home/oseloka/pyprojects/maplecourt_py/MapleCourt_propertyMgt/src/notifications
/home/oseloka/pyprojects/maplecourt_py/MapleCourt_propertyMgt/src/notifications
/home/oseloka/pyprojects/maplecourt_py/MapleCourt_propertyMgt/src/notifications
--- Logging error ---
Traceback (most recent call last):
  File "/home/oseloka/pyprojects/maplecourt_py/venv_mc/lib/python3.10/site-packages/urllib3/connection.py", line 174, in _new_conn
    conn = connection.create_connection(
  File "/home/oseloka/pyprojects/maplecourt_py/venv_mc/lib/python3.10/site-packages/urllib3/util/connection.py", line 72, in create_connection
    for res in socket.getaddrinfo(host, port, family, socket.SOCK_STREAM):
  File "/usr/lib/python3.10/socket.py", line 955, in getaddrinfo
    for res in _socket.getaddrinfo(host, port, family, type, proto, flags):
socket.gaierror: [Errno -3] Temporary failure in name resolution

During handling of the above exception, another exception occurred:

Traceback (most recent call last):
  File "/home/oseloka/pyprojects/maplecourt_py/venv_mc/lib/python3.10/site-packages/urllib3/connectionpool.py", line 703, in urlopen
    httplib_response = self._make_request(
  File "/home/oseloka/pyprojects/maplecourt_py/venv_mc/lib/python3.10/site-packages/urllib3/connectionpool.py", line 386, in _make_request
    self._validate_conn(conn)
  File "/home/oseloka/pyprojects/maplecourt_py/venv_mc/lib/python3.10/site-packages/urllib3/connectionpool.py", line 1042, in _validate_conn
    conn.connect()
  File "/home/oseloka/pyprojects/maplecourt_py/venv_mc/lib/python3.10/site-packages/urllib3/connection.py", line 358, in connect
    self.sock = conn = self._new_conn()
  File "/home/oseloka/pyprojects/maplecourt_py/venv_mc/lib/python3.10/site-packages/urllib3/connection.py", line 186, in _new_conn
    raise NewConnectionError(
urllib3.exceptions.NewConnectionError: <urllib3.connection.HTTPSConnection object at 0x7fa7ff50ece0>: Failed to establish a new connection: [Errno -3] Temporary failure in name resolution

During handling of the above exception, another exception occurred:

Traceback (most recent call last):
  File "/home/oseloka/pyprojects/maplecourt_py/venv_mc/lib/python3.10/site-packages/requests/adapters.py", line 489, in send
    resp = conn.urlopen(
  File "/home/oseloka/pyprojects/maplecourt_py/venv_mc/lib/python3.10/site-packages/urllib3/connectionpool.py", line 787, in urlopen
    retries = retries.increment(
  File "/home/oseloka/pyprojects/maplecourt_py/venv_mc/lib/python3.10/site-packages/urllib3/util/retry.py", line 592, in increment
    raise MaxRetryError(_pool, url, error or ResponseError(cause))
urllib3.exceptions.MaxRetryError: HTTPSConnectionPool(host='oauth2.googleapis.com', port=443): Max retries exceeded with url: /token (Caused by NewConnectionError('<urllib3.connection.HTTPSConnection object at 0x7fa7ff50ece0>: Failed to establish a new connection: [Errno -3] Temporary failure in name resolution'))

During handling of the above exception, another exception occurred:

Traceback (most recent call last):
  File "/home/oseloka/pyprojects/maplecourt_py/venv_mc/lib/python3.10/site-packages/google/auth/transport/requests.py", line 193, in __call__
    response = self.session.request(
  File "/home/oseloka/pyprojects/maplecourt_py/venv_mc/lib/python3.10/site-packages/requests/sessions.py", line 587, in request
    resp = self.send(prep, **send_kwargs)
  File "/home/oseloka/pyprojects/maplecourt_py/venv_mc/lib/python3.10/site-packages/requests/sessions.py", line 701, in send
    r = adapter.send(request, **kwargs)
  File "/home/oseloka/pyprojects/maplecourt_py/venv_mc/lib/python3.10/site-packages/requests/adapters.py", line 565, in send
    raise ConnectionError(e, request=request)
requests.exceptions.ConnectionError: HTTPSConnectionPool(host='oauth2.googleapis.com', port=443): Max retries exceeded with url: /token (Caused by NewConnectionError('<urllib3.connection.HTTPSConnection object at 0x7fa7ff50ece0>: Failed to establish a new connection: [Errno -3] Temporary failure in name resolution'))

The above exception was the direct cause of the following exception:

Traceback (most recent call last):
  File "/home/oseloka/pyprojects/maplecourt_py/MapleCourt_propertyMgt/src/utils/credentials.py", line 41, in get_google_credentials
    creds.refresh(Request())
  File "/home/oseloka/pyprojects/maplecourt_py/venv_mc/lib/python3.10/site-packages/google/oauth2/credentials.py", line 335, in refresh
    ) = reauth.refresh_grant(
  File "/home/oseloka/pyprojects/maplecourt_py/venv_mc/lib/python3.10/site-packages/google/oauth2/reauth.py", line 324, in refresh_grant
    response_status_ok, response_data, retryable_error = _client._token_endpoint_request_no_throw(
  File "/home/oseloka/pyprojects/maplecourt_py/venv_mc/lib/python3.10/site-packages/google/oauth2/_client.py", line 213, in _token_endpoint_request_no_throw
    request_succeeded, response_data, retryable_error = _perform_request()
  File "/home/oseloka/pyprojects/maplecourt_py/venv_mc/lib/python3.10/site-packages/google/oauth2/_client.py", line 189, in _perform_request
    response = request(
  File "/home/oseloka/pyprojects/maplecourt_py/venv_mc/lib/python3.10/site-packages/google/auth/transport/requests.py", line 199, in __call__
    six.raise_from(new_exc, caught_exc)
  File "<string>", line 3, in raise_from
google.auth.exceptions.TransportError: HTTPSConnectionPool(host='oauth2.googleapis.com', port=443): Max retries exceeded with url: /token (Caused by NewConnectionError('<urllib3.connection.HTTPSConnection object at 0x7fa7ff50ece0>: Failed to establish a new connection: [Errno -3] Temporary failure in name resolution'))

During handling of the above exception, another exception occurred:

Traceback (most recent call last):
  File "/usr/lib/python3.10/logging/__init__.py", line 1100, in emit
    msg = self.format(record)
  File "/usr/lib/python3.10/logging/__init__.py", line 943, in format
    return fmt.format(record)
  File "/usr/lib/python3.10/logging/__init__.py", line 678, in format
    record.message = record.getMessage()
  File "/usr/lib/python3.10/logging/__init__.py", line 368, in getMessage
    msg = msg % self.args
TypeError: not all arguments converted during string formatting
Call stack:
  File "/home/oseloka/pyprojects/maplecourt_py/MapleCourt_propertyMgt/src/notifications/rent_notice_email.py", line 146, in <module>
    send_upcoming_rent_email(logger)
  File "/home/oseloka/pyprojects/maplecourt_py/MapleCourt_propertyMgt/src/notifications/rent_notice_email.py", line 118, in send_upcoming_rent_email
    success = send_email("Upcoming Rent Renewal", app_email, email, body, logger_instance)
  File "/home/oseloka/pyprojects/maplecourt_py/MapleCourt_propertyMgt/src/utils/comms.py", line 29, in send_email
    service = get_google_credentials(logger_instance)
  File "/home/oseloka/pyprojects/maplecourt_py/MapleCourt_propertyMgt/src/utils/credentials.py", line 46, in get_google_credentials
    logger_instance.error("Failed to refresh credentials:", e)
Message: 'Failed to refresh credentials:'
Arguments: (TransportError(ConnectionError(MaxRetryError("HTTPSConnectionPool(host='oauth2.googleapis.com', port=443): Max retries exceeded with url: /token (Caused by NewConnectionError('<urllib3.connection.HTTPSConnection object at 0x7fa7ff50ece0>: Failed to establish a new connection: [Errno -3] Temporary failure in name resolution'))"))),)
/home/oseloka/pyprojects/maplecourt_py/MapleCourt_propertyMgt/src/notifications
--- Logging error ---
Traceback (most recent call last):
  File "/home/oseloka/pyprojects/maplecourt_py/venv_mc/lib/python3.10/site-packages/urllib3/connection.py", line 174, in _new_conn
    conn = connection.create_connection(
  File "/home/oseloka/pyprojects/maplecourt_py/venv_mc/lib/python3.10/site-packages/urllib3/util/connection.py", line 72, in create_connection
    for res in socket.getaddrinfo(host, port, family, socket.SOCK_STREAM):
  File "/usr/lib/python3.10/socket.py", line 955, in getaddrinfo
    for res in _socket.getaddrinfo(host, port, family, type, proto, flags):
socket.gaierror: [Errno -3] Temporary failure in name resolution

During handling of the above exception, another exception occurred:

Traceback (most recent call last):
  File "/home/oseloka/pyprojects/maplecourt_py/venv_mc/lib/python3.10/site-packages/urllib3/connectionpool.py", line 703, in urlopen
    httplib_response = self._make_request(
  File "/home/oseloka/pyprojects/maplecourt_py/venv_mc/lib/python3.10/site-packages/urllib3/connectionpool.py", line 386, in _make_request
    self._validate_conn(conn)
  File "/home/oseloka/pyprojects/maplecourt_py/venv_mc/lib/python3.10/site-packages/urllib3/connectionpool.py", line 1042, in _validate_conn
    conn.connect()
  File "/home/oseloka/pyprojects/maplecourt_py/venv_mc/lib/python3.10/site-packages/urllib3/connection.py", line 358, in connect
    self.sock = conn = self._new_conn()
  File "/home/oseloka/pyprojects/maplecourt_py/venv_mc/lib/python3.10/site-packages/urllib3/connection.py", line 186, in _new_conn
    raise NewConnectionError(
urllib3.exceptions.NewConnectionError: <urllib3.connection.HTTPSConnection object at 0x7fcf99bec9d0>: Failed to establish a new connection: [Errno -3] Temporary failure in name resolution

During handling of the above exception, another exception occurred:

Traceback (most recent call last):
  File "/home/oseloka/pyprojects/maplecourt_py/venv_mc/lib/python3.10/site-packages/requests/adapters.py", line 489, in send
    resp = conn.urlopen(
  File "/home/oseloka/pyprojects/maplecourt_py/venv_mc/lib/python3.10/site-packages/urllib3/connectionpool.py", line 787, in urlopen
    retries = retries.increment(
  File "/home/oseloka/pyprojects/maplecourt_py/venv_mc/lib/python3.10/site-packages/urllib3/util/retry.py", line 592, in increment
    raise MaxRetryError(_pool, url, error or ResponseError(cause))
urllib3.exceptions.MaxRetryError: HTTPSConnectionPool(host='oauth2.googleapis.com', port=443): Max retries exceeded with url: /token (Caused by NewConnectionError('<urllib3.connection.HTTPSConnection object at 0x7fcf99bec9d0>: Failed to establish a new connection: [Errno -3] Temporary failure in name resolution'))

During handling of the above exception, another exception occurred:

Traceback (most recent call last):
  File "/home/oseloka/pyprojects/maplecourt_py/venv_mc/lib/python3.10/site-packages/google/auth/transport/requests.py", line 193, in __call__
    response = self.session.request(
  File "/home/oseloka/pyprojects/maplecourt_py/venv_mc/lib/python3.10/site-packages/requests/sessions.py", line 587, in request
    resp = self.send(prep, **send_kwargs)
  File "/home/oseloka/pyprojects/maplecourt_py/venv_mc/lib/python3.10/site-packages/requests/sessions.py", line 701, in send
    r = adapter.send(request, **kwargs)
  File "/home/oseloka/pyprojects/maplecourt_py/venv_mc/lib/python3.10/site-packages/requests/adapters.py", line 565, in send
    raise ConnectionError(e, request=request)
requests.exceptions.ConnectionError: HTTPSConnectionPool(host='oauth2.googleapis.com', port=443): Max retries exceeded with url: /token (Caused by NewConnectionError('<urllib3.connection.HTTPSConnection object at 0x7fcf99bec9d0>: Failed to establish a new connection: [Errno -3] Temporary failure in name resolution'))

The above exception was the direct cause of the following exception:

Traceback (most recent call last):
  File "/home/oseloka/pyprojects/maplecourt_py/MapleCourt_propertyMgt/src/utils/credentials.py", line 41, in get_google_credentials
    creds.refresh(Request())
  File "/home/oseloka/pyprojects/maplecourt_py/venv_mc/lib/python3.10/site-packages/google/oauth2/credentials.py", line 335, in refresh
    ) = reauth.refresh_grant(
  File "/home/oseloka/pyprojects/maplecourt_py/venv_mc/lib/python3.10/site-packages/google/oauth2/reauth.py", line 324, in refresh_grant
    response_status_ok, response_data, retryable_error = _client._token_endpoint_request_no_throw(
  File "/home/oseloka/pyprojects/maplecourt_py/venv_mc/lib/python3.10/site-packages/google/oauth2/_client.py", line 213, in _token_endpoint_request_no_throw
    request_succeeded, response_data, retryable_error = _perform_request()
  File "/home/oseloka/pyprojects/maplecourt_py/venv_mc/lib/python3.10/site-packages/google/oauth2/_client.py", line 189, in _perform_request
    response = request(
  File "/home/oseloka/pyprojects/maplecourt_py/venv_mc/lib/python3.10/site-packages/google/auth/transport/requests.py", line 199, in __call__
    six.raise_from(new_exc, caught_exc)
  File "<string>", line 3, in raise_from
google.auth.exceptions.TransportError: HTTPSConnectionPool(host='oauth2.googleapis.com', port=443): Max retries exceeded with url: /token (Caused by NewConnectionError('<urllib3.connection.HTTPSConnection object at 0x7fcf99bec9d0>: Failed to establish a new connection: [Errno -3] Temporary failure in name resolution'))

During handling of the above exception, another exception occurred:

Traceback (most recent call last):
  File "/usr/lib/python3.10/logging/__init__.py", line 1100, in emit
    msg = self.format(record)
  File "/usr/lib/python3.10/logging/__init__.py", line 943, in format
    return fmt.format(record)
  File "/usr/lib/python3.10/logging/__init__.py", line 678, in format
    record.message = record.getMessage()
  File "/usr/lib/python3.10/logging/__init__.py", line 368, in getMessage
    msg = msg % self.args
TypeError: not all arguments converted during string formatting
Call stack:
  File "/home/oseloka/pyprojects/maplecourt_py/MapleCourt_propertyMgt/src/notifications/rent_notice_email.py", line 146, in <module>
    send_upcoming_rent_email(logger)
  File "/home/oseloka/pyprojects/maplecourt_py/MapleCourt_propertyMgt/src/notifications/rent_notice_email.py", line 118, in send_upcoming_rent_email
    success = send_email("Upcoming Rent Renewal", app_email, email, body, logger_instance)
  File "/home/oseloka/pyprojects/maplecourt_py/MapleCourt_propertyMgt/src/utils/comms.py", line 29, in send_email
    service = get_google_credentials(logger_instance)
  File "/home/oseloka/pyprojects/maplecourt_py/MapleCourt_propertyMgt/src/utils/credentials.py", line 46, in get_google_credentials
    logger_instance.error("Failed to refresh credentials:", e)
Message: 'Failed to refresh credentials:'
Arguments: (TransportError(ConnectionError(MaxRetryError("HTTPSConnectionPool(host='oauth2.googleapis.com', port=443): Max retries exceeded with url: /token (Caused by NewConnectionError('<urllib3.connection.HTTPSConnection object at 0x7fcf99bec9d0>: Failed to establish a new connection: [Errno -3] Temporary failure in name resolution'))"))),)
/home/oseloka/pyprojects/maplecourt_py/MapleCourt_propertyMgt/src/notifications
--- Logging error ---
Traceback (most recent call last):
  File "/home/oseloka/pyprojects/maplecourt_py/venv_mc/lib/python3.10/site-packages/urllib3/connection.py", line 174, in _new_conn
    conn = connection.create_connection(
  File "/home/oseloka/pyprojects/maplecourt_py/venv_mc/lib/python3.10/site-packages/urllib3/util/connection.py", line 72, in create_connection
    for res in socket.getaddrinfo(host, port, family, socket.SOCK_STREAM):
  File "/usr/lib/python3.10/socket.py", line 955, in getaddrinfo
    for res in _socket.getaddrinfo(host, port, family, type, proto, flags):
socket.gaierror: [Errno -3] Temporary failure in name resolution

During handling of the above exception, another exception occurred:

Traceback (most recent call last):
  File "/home/oseloka/pyprojects/maplecourt_py/venv_mc/lib/python3.10/site-packages/urllib3/connectionpool.py", line 703, in urlopen
    httplib_response = self._make_request(
  File "/home/oseloka/pyprojects/maplecourt_py/venv_mc/lib/python3.10/site-packages/urllib3/connectionpool.py", line 386, in _make_request
    self._validate_conn(conn)
  File "/home/oseloka/pyprojects/maplecourt_py/venv_mc/lib/python3.10/site-packages/urllib3/connectionpool.py", line 1042, in _validate_conn
    conn.connect()
  File "/home/oseloka/pyprojects/maplecourt_py/venv_mc/lib/python3.10/site-packages/urllib3/connection.py", line 358, in connect
    self.sock = conn = self._new_conn()
  File "/home/oseloka/pyprojects/maplecourt_py/venv_mc/lib/python3.10/site-packages/urllib3/connection.py", line 186, in _new_conn
    raise NewConnectionError(
urllib3.exceptions.NewConnectionError: <urllib3.connection.HTTPSConnection object at 0x7f6e15fe47c0>: Failed to establish a new connection: [Errno -3] Temporary failure in name resolution

During handling of the above exception, another exception occurred:

Traceback (most recent call last):
  File "/home/oseloka/pyprojects/maplecourt_py/venv_mc/lib/python3.10/site-packages/requests/adapters.py", line 489, in send
    resp = conn.urlopen(
  File "/home/oseloka/pyprojects/maplecourt_py/venv_mc/lib/python3.10/site-packages/urllib3/connectionpool.py", line 787, in urlopen
    retries = retries.increment(
  File "/home/oseloka/pyprojects/maplecourt_py/venv_mc/lib/python3.10/site-packages/urllib3/util/retry.py", line 592, in increment
    raise MaxRetryError(_pool, url, error or ResponseError(cause))
urllib3.exceptions.MaxRetryError: HTTPSConnectionPool(host='oauth2.googleapis.com', port=443): Max retries exceeded with url: /token (Caused by NewConnectionError('<urllib3.connection.HTTPSConnection object at 0x7f6e15fe47c0>: Failed to establish a new connection: [Errno -3] Temporary failure in name resolution'))

During handling of the above exception, another exception occurred:

Traceback (most recent call last):
  File "/home/oseloka/pyprojects/maplecourt_py/venv_mc/lib/python3.10/site-packages/google/auth/transport/requests.py", line 193, in __call__
    response = self.session.request(
  File "/home/oseloka/pyprojects/maplecourt_py/venv_mc/lib/python3.10/site-packages/requests/sessions.py", line 587, in request
    resp = self.send(prep, **send_kwargs)
  File "/home/oseloka/pyprojects/maplecourt_py/venv_mc/lib/python3.10/site-packages/requests/sessions.py", line 701, in send
    r = adapter.send(request, **kwargs)
  File "/home/oseloka/pyprojects/maplecourt_py/venv_mc/lib/python3.10/site-packages/requests/adapters.py", line 565, in send
    raise ConnectionError(e, request=request)
requests.exceptions.ConnectionError: HTTPSConnectionPool(host='oauth2.googleapis.com', port=443): Max retries exceeded with url: /token (Caused by NewConnectionError('<urllib3.connection.HTTPSConnection object at 0x7f6e15fe47c0>: Failed to establish a new connection: [Errno -3] Temporary failure in name resolution'))

The above exception was the direct cause of the following exception:

Traceback (most recent call last):
  File "/home/oseloka/pyprojects/maplecourt_py/MapleCourt_propertyMgt/src/utils/credentials.py", line 41, in get_google_credentials
    creds.refresh(Request())
  File "/home/oseloka/pyprojects/maplecourt_py/venv_mc/lib/python3.10/site-packages/google/oauth2/credentials.py", line 335, in refresh
    ) = reauth.refresh_grant(
  File "/home/oseloka/pyprojects/maplecourt_py/venv_mc/lib/python3.10/site-packages/google/oauth2/reauth.py", line 324, in refresh_grant
    response_status_ok, response_data, retryable_error = _client._token_endpoint_request_no_throw(
  File "/home/oseloka/pyprojects/maplecourt_py/venv_mc/lib/python3.10/site-packages/google/oauth2/_client.py", line 213, in _token_endpoint_request_no_throw
    request_succeeded, response_data, retryable_error = _perform_request()
  File "/home/oseloka/pyprojects/maplecourt_py/venv_mc/lib/python3.10/site-packages/google/oauth2/_client.py", line 189, in _perform_request
    response = request(
  File "/home/oseloka/pyprojects/maplecourt_py/venv_mc/lib/python3.10/site-packages/google/auth/transport/requests.py", line 199, in __call__
    six.raise_from(new_exc, caught_exc)
  File "<string>", line 3, in raise_from
google.auth.exceptions.TransportError: HTTPSConnectionPool(host='oauth2.googleapis.com', port=443): Max retries exceeded with url: /token (Caused by NewConnectionError('<urllib3.connection.HTTPSConnection object at 0x7f6e15fe47c0>: Failed to establish a new connection: [Errno -3] Temporary failure in name resolution'))

During handling of the above exception, another exception occurred:

Traceback (most recent call last):
  File "/usr/lib/python3.10/logging/__init__.py", line 1100, in emit
    msg = self.format(record)
  File "/usr/lib/python3.10/logging/__init__.py", line 943, in format
    return fmt.format(record)
  File "/usr/lib/python3.10/logging/__init__.py", line 678, in format
    record.message = record.getMessage()
  File "/usr/lib/python3.10/logging/__init__.py", line 368, in getMessage
    msg = msg % self.args
TypeError: not all arguments converted during string formatting
Call stack:
  File "/home/oseloka/pyprojects/maplecourt_py/MapleCourt_propertyMgt/src/notifications/rent_notice_email.py", line 146, in <module>
    send_upcoming_rent_email(logger)
  File "/home/oseloka/pyprojects/maplecourt_py/MapleCourt_propertyMgt/src/notifications/rent_notice_email.py", line 118, in send_upcoming_rent_email
    success = send_email("Upcoming Rent Renewal", app_email, email, body, logger_instance)
  File "/home/oseloka/pyprojects/maplecourt_py/MapleCourt_propertyMgt/src/utils/comms.py", line 29, in send_email
    service = get_google_credentials(logger_instance)
  File "/home/oseloka/pyprojects/maplecourt_py/MapleCourt_propertyMgt/src/utils/credentials.py", line 46, in get_google_credentials
    logger_instance.error("Failed to refresh credentials:", e)
Message: 'Failed to refresh credentials:'
Arguments: (TransportError(ConnectionError(MaxRetryError("HTTPSConnectionPool(host='oauth2.googleapis.com', port=443): Max retries exceeded with url: /token (Caused by NewConnectionError('<urllib3.connection.HTTPSConnection object at 0x7f6e15fe47c0>: Failed to establish a new connection: [Errno -3] Temporary failure in name resolution'))"))),)
/home/oseloka/pyprojects/maplecourt_py/MapleCourt_propertyMgt/src/notifications
--- Logging error ---
Traceback (most recent call last):
  File "/home/oseloka/pyprojects/maplecourt_py/venv_mc/lib/python3.10/site-packages/urllib3/connection.py", line 174, in _new_conn
    conn = connection.create_connection(
  File "/home/oseloka/pyprojects/maplecourt_py/venv_mc/lib/python3.10/site-packages/urllib3/util/connection.py", line 72, in create_connection
    for res in socket.getaddrinfo(host, port, family, socket.SOCK_STREAM):
  File "/usr/lib/python3.10/socket.py", line 955, in getaddrinfo
    for res in _socket.getaddrinfo(host, port, family, type, proto, flags):
socket.gaierror: [Errno -3] Temporary failure in name resolution

During handling of the above exception, another exception occurred:

Traceback (most recent call last):
  File "/home/oseloka/pyprojects/maplecourt_py/venv_mc/lib/python3.10/site-packages/urllib3/connectionpool.py", line 703, in urlopen
    httplib_response = self._make_request(
  File "/home/oseloka/pyprojects/maplecourt_py/venv_mc/lib/python3.10/site-packages/urllib3/connectionpool.py", line 386, in _make_request
    self._validate_conn(conn)
  File "/home/oseloka/pyprojects/maplecourt_py/venv_mc/lib/python3.10/site-packages/urllib3/connectionpool.py", line 1042, in _validate_conn
    conn.connect()
  File "/home/oseloka/pyprojects/maplecourt_py/venv_mc/lib/python3.10/site-packages/urllib3/connection.py", line 358, in connect
    self.sock = conn = self._new_conn()
  File "/home/oseloka/pyprojects/maplecourt_py/venv_mc/lib/python3.10/site-packages/urllib3/connection.py", line 186, in _new_conn
    raise NewConnectionError(
urllib3.exceptions.NewConnectionError: <urllib3.connection.HTTPSConnection object at 0x7fb624be4670>: Failed to establish a new connection: [Errno -3] Temporary failure in name resolution

During handling of the above exception, another exception occurred:

Traceback (most recent call last):
  File "/home/oseloka/pyprojects/maplecourt_py/venv_mc/lib/python3.10/site-packages/requests/adapters.py", line 489, in send
    resp = conn.urlopen(
  File "/home/oseloka/pyprojects/maplecourt_py/venv_mc/lib/python3.10/site-packages/urllib3/connectionpool.py", line 787, in urlopen
    retries = retries.increment(
  File "/home/oseloka/pyprojects/maplecourt_py/venv_mc/lib/python3.10/site-packages/urllib3/util/retry.py", line 592, in increment
    raise MaxRetryError(_pool, url, error or ResponseError(cause))
urllib3.exceptions.MaxRetryError: HTTPSConnectionPool(host='oauth2.googleapis.com', port=443): Max retries exceeded with url: /token (Caused by NewConnectionError('<urllib3.connection.HTTPSConnection object at 0x7fb624be4670>: Failed to establish a new connection: [Errno -3] Temporary failure in name resolution'))

During handling of the above exception, another exception occurred:

Traceback (most recent call last):
  File "/home/oseloka/pyprojects/maplecourt_py/venv_mc/lib/python3.10/site-packages/google/auth/transport/requests.py", line 193, in __call__
    response = self.session.request(
  File "/home/oseloka/pyprojects/maplecourt_py/venv_mc/lib/python3.10/site-packages/requests/sessions.py", line 587, in request
    resp = self.send(prep, **send_kwargs)
  File "/home/oseloka/pyprojects/maplecourt_py/venv_mc/lib/python3.10/site-packages/requests/sessions.py", line 701, in send
    r = adapter.send(request, **kwargs)
  File "/home/oseloka/pyprojects/maplecourt_py/venv_mc/lib/python3.10/site-packages/requests/adapters.py", line 565, in send
    raise ConnectionError(e, request=request)
requests.exceptions.ConnectionError: HTTPSConnectionPool(host='oauth2.googleapis.com', port=443): Max retries exceeded with url: /token (Caused by NewConnectionError('<urllib3.connection.HTTPSConnection object at 0x7fb624be4670>: Failed to establish a new connection: [Errno -3] Temporary failure in name resolution'))

The above exception was the direct cause of the following exception:

Traceback (most recent call last):
  File "/home/oseloka/pyprojects/maplecourt_py/MapleCourt_propertyMgt/src/utils/credentials.py", line 41, in get_google_credentials
    creds.refresh(Request())
  File "/home/oseloka/pyprojects/maplecourt_py/venv_mc/lib/python3.10/site-packages/google/oauth2/credentials.py", line 335, in refresh
    ) = reauth.refresh_grant(
  File "/home/oseloka/pyprojects/maplecourt_py/venv_mc/lib/python3.10/site-packages/google/oauth2/reauth.py", line 324, in refresh_grant
    response_status_ok, response_data, retryable_error = _client._token_endpoint_request_no_throw(
  File "/home/oseloka/pyprojects/maplecourt_py/venv_mc/lib/python3.10/site-packages/google/oauth2/_client.py", line 213, in _token_endpoint_request_no_throw
    request_succeeded, response_data, retryable_error = _perform_request()
  File "/home/oseloka/pyprojects/maplecourt_py/venv_mc/lib/python3.10/site-packages/google/oauth2/_client.py", line 189, in _perform_request
    response = request(
  File "/home/oseloka/pyprojects/maplecourt_py/venv_mc/lib/python3.10/site-packages/google/auth/transport/requests.py", line 199, in __call__
    six.raise_from(new_exc, caught_exc)
  File "<string>", line 3, in raise_from
google.auth.exceptions.TransportError: HTTPSConnectionPool(host='oauth2.googleapis.com', port=443): Max retries exceeded with url: /token (Caused by NewConnectionError('<urllib3.connection.HTTPSConnection object at 0x7fb624be4670>: Failed to establish a new connection: [Errno -3] Temporary failure in name resolution'))

During handling of the above exception, another exception occurred:

Traceback (most recent call last):
  File "/usr/lib/python3.10/logging/__init__.py", line 1100, in emit
    msg = self.format(record)
  File "/usr/lib/python3.10/logging/__init__.py", line 943, in format
    return fmt.format(record)
  File "/usr/lib/python3.10/logging/__init__.py", line 678, in format
    record.message = record.getMessage()
  File "/usr/lib/python3.10/logging/__init__.py", line 368, in getMessage
    msg = msg % self.args
TypeError: not all arguments converted during string formatting
Call stack:
  File "/home/oseloka/pyprojects/maplecourt_py/MapleCourt_propertyMgt/src/notifications/rent_notice_email.py", line 146, in <module>
    send_upcoming_rent_email(logger)
  File "/home/oseloka/pyprojects/maplecourt_py/MapleCourt_propertyMgt/src/notifications/rent_notice_email.py", line 118, in send_upcoming_rent_email
    success = send_email("Upcoming Rent Renewal", app_email, email, body, logger_instance)
  File "/home/oseloka/pyprojects/maplecourt_py/MapleCourt_propertyMgt/src/utils/comms.py", line 29, in send_email
    service = get_google_credentials(logger_instance)
  File "/home/oseloka/pyprojects/maplecourt_py/MapleCourt_propertyMgt/src/utils/credentials.py", line 46, in get_google_credentials
    logger_instance.error("Failed to refresh credentials:", e)
Message: 'Failed to refresh credentials:'
Arguments: (TransportError(ConnectionError(MaxRetryError("HTTPSConnectionPool(host='oauth2.googleapis.com', port=443): Max retries exceeded with url: /token (Caused by NewConnectionError('<urllib3.connection.HTTPSConnection object at 0x7fb624be4670>: Failed to establish a new connection: [Errno -3] Temporary failure in name resolution'))"))),)
/home/oseloka/pyprojects/maplecourt_py/MapleCourt_propertyMgt/src/notifications
--- Logging error ---
Traceback (most recent call last):
  File "/home/oseloka/pyprojects/maplecourt_py/venv_mc/lib/python3.10/site-packages/urllib3/connection.py", line 174, in _new_conn
    conn = connection.create_connection(
  File "/home/oseloka/pyprojects/maplecourt_py/venv_mc/lib/python3.10/site-packages/urllib3/util/connection.py", line 72, in create_connection
    for res in socket.getaddrinfo(host, port, family, socket.SOCK_STREAM):
  File "/usr/lib/python3.10/socket.py", line 955, in getaddrinfo
    for res in _socket.getaddrinfo(host, port, family, type, proto, flags):
socket.gaierror: [Errno -3] Temporary failure in name resolution

During handling of the above exception, another exception occurred:

Traceback (most recent call last):
  File "/home/oseloka/pyprojects/maplecourt_py/venv_mc/lib/python3.10/site-packages/urllib3/connectionpool.py", line 703, in urlopen
    httplib_response = self._make_request(
  File "/home/oseloka/pyprojects/maplecourt_py/venv_mc/lib/python3.10/site-packages/urllib3/connectionpool.py", line 386, in _make_request
    self._validate_conn(conn)
  File "/home/oseloka/pyprojects/maplecourt_py/venv_mc/lib/python3.10/site-packages/urllib3/connectionpool.py", line 1042, in _validate_conn
    conn.connect()
  File "/home/oseloka/pyprojects/maplecourt_py/venv_mc/lib/python3.10/site-packages/urllib3/connection.py", line 358, in connect
    self.sock = conn = self._new_conn()
  File "/home/oseloka/pyprojects/maplecourt_py/venv_mc/lib/python3.10/site-packages/urllib3/connection.py", line 186, in _new_conn
    raise NewConnectionError(
urllib3.exceptions.NewConnectionError: <urllib3.connection.HTTPSConnection object at 0x7ff60591b1f0>: Failed to establish a new connection: [Errno -3] Temporary failure in name resolution

During handling of the above exception, another exception occurred:

Traceback (most recent call last):
  File "/home/oseloka/pyprojects/maplecourt_py/venv_mc/lib/python3.10/site-packages/requests/adapters.py", line 489, in send
    resp = conn.urlopen(
  File "/home/oseloka/pyprojects/maplecourt_py/venv_mc/lib/python3.10/site-packages/urllib3/connectionpool.py", line 787, in urlopen
    retries = retries.increment(
  File "/home/oseloka/pyprojects/maplecourt_py/venv_mc/lib/python3.10/site-packages/urllib3/util/retry.py", line 592, in increment
    raise MaxRetryError(_pool, url, error or ResponseError(cause))
urllib3.exceptions.MaxRetryError: HTTPSConnectionPool(host='oauth2.googleapis.com', port=443): Max retries exceeded with url: /token (Caused by NewConnectionError('<urllib3.connection.HTTPSConnection object at 0x7ff60591b1f0>: Failed to establish a new connection: [Errno -3] Temporary failure in name resolution'))

During handling of the above exception, another exception occurred:

Traceback (most recent call last):
  File "/home/oseloka/pyprojects/maplecourt_py/venv_mc/lib/python3.10/site-packages/google/auth/transport/requests.py", line 193, in __call__
    response = self.session.request(
  File "/home/oseloka/pyprojects/maplecourt_py/venv_mc/lib/python3.10/site-packages/requests/sessions.py", line 587, in request
    resp = self.send(prep, **send_kwargs)
  File "/home/oseloka/pyprojects/maplecourt_py/venv_mc/lib/python3.10/site-packages/requests/sessions.py", line 701, in send
    r = adapter.send(request, **kwargs)
  File "/home/oseloka/pyprojects/maplecourt_py/venv_mc/lib/python3.10/site-packages/requests/adapters.py", line 565, in send
    raise ConnectionError(e, request=request)
requests.exceptions.ConnectionError: HTTPSConnectionPool(host='oauth2.googleapis.com', port=443): Max retries exceeded with url: /token (Caused by NewConnectionError('<urllib3.connection.HTTPSConnection object at 0x7ff60591b1f0>: Failed to establish a new connection: [Errno -3] Temporary failure in name resolution'))

The above exception was the direct cause of the following exception:

Traceback (most recent call last):
  File "/home/oseloka/pyprojects/maplecourt_py/MapleCourt_propertyMgt/src/utils/credentials.py", line 41, in get_google_credentials
    creds.refresh(Request())
  File "/home/oseloka/pyprojects/maplecourt_py/venv_mc/lib/python3.10/site-packages/google/oauth2/credentials.py", line 335, in refresh
    ) = reauth.refresh_grant(
  File "/home/oseloka/pyprojects/maplecourt_py/venv_mc/lib/python3.10/site-packages/google/oauth2/reauth.py", line 324, in refresh_grant
    response_status_ok, response_data, retryable_error = _client._token_endpoint_request_no_throw(
  File "/home/oseloka/pyprojects/maplecourt_py/venv_mc/lib/python3.10/site-packages/google/oauth2/_client.py", line 213, in _token_endpoint_request_no_throw
    request_succeeded, response_data, retryable_error = _perform_request()
  File "/home/oseloka/pyprojects/maplecourt_py/venv_mc/lib/python3.10/site-packages/google/oauth2/_client.py", line 189, in _perform_request
    response = request(
  File "/home/oseloka/pyprojects/maplecourt_py/venv_mc/lib/python3.10/site-packages/google/auth/transport/requests.py", line 199, in __call__
    six.raise_from(new_exc, caught_exc)
  File "<string>", line 3, in raise_from
google.auth.exceptions.TransportError: HTTPSConnectionPool(host='oauth2.googleapis.com', port=443): Max retries exceeded with url: /token (Caused by NewConnectionError('<urllib3.connection.HTTPSConnection object at 0x7ff60591b1f0>: Failed to establish a new connection: [Errno -3] Temporary failure in name resolution'))

During handling of the above exception, another exception occurred:

Traceback (most recent call last):
  File "/usr/lib/python3.10/logging/__init__.py", line 1100, in emit
    msg = self.format(record)
  File "/usr/lib/python3.10/logging/__init__.py", line 943, in format
    return fmt.format(record)
  File "/usr/lib/python3.10/logging/__init__.py", line 678, in format
    record.message = record.getMessage()
  File "/usr/lib/python3.10/logging/__init__.py", line 368, in getMessage
    msg = msg % self.args
TypeError: not all arguments converted during string formatting
Call stack:
  File "/home/oseloka/pyprojects/maplecourt_py/MapleCourt_propertyMgt/src/notifications/rent_notice_email.py", line 146, in <module>
    send_upcoming_rent_email(logger)
  File "/home/oseloka/pyprojects/maplecourt_py/MapleCourt_propertyMgt/src/notifications/rent_notice_email.py", line 118, in send_upcoming_rent_email
    success = send_email("Upcoming Rent Renewal", app_email, email, body, logger_instance)
  File "/home/oseloka/pyprojects/maplecourt_py/MapleCourt_propertyMgt/src/utils/comms.py", line 29, in send_email
    service = get_google_credentials(logger_instance)
  File "/home/oseloka/pyprojects/maplecourt_py/MapleCourt_propertyMgt/src/utils/credentials.py", line 46, in get_google_credentials
    logger_instance.error("Failed to refresh credentials:", e)
Message: 'Failed to refresh credentials:'
Arguments: (TransportError(ConnectionError(MaxRetryError("HTTPSConnectionPool(host='oauth2.googleapis.com', port=443): Max retries exceeded with url: /token (Caused by NewConnectionError('<urllib3.connection.HTTPSConnection object at 0x7ff60591b1f0>: Failed to establish a new connection: [Errno -3] Temporary failure in name resolution'))"))),)
/home/oseloka/pyprojects/maplecourt_py/MapleCourt_propertyMgt/src/notifications
--- Logging error ---
Traceback (most recent call last):
  File "/home/oseloka/pyprojects/maplecourt_py/venv_mc/lib/python3.10/site-packages/urllib3/connection.py", line 174, in _new_conn
    conn = connection.create_connection(
  File "/home/oseloka/pyprojects/maplecourt_py/venv_mc/lib/python3.10/site-packages/urllib3/util/connection.py", line 72, in create_connection
    for res in socket.getaddrinfo(host, port, family, socket.SOCK_STREAM):
  File "/usr/lib/python3.10/socket.py", line 955, in getaddrinfo
    for res in _socket.getaddrinfo(host, port, family, type, proto, flags):
socket.gaierror: [Errno -3] Temporary failure in name resolution

During handling of the above exception, another exception occurred:

Traceback (most recent call last):
  File "/home/oseloka/pyprojects/maplecourt_py/venv_mc/lib/python3.10/site-packages/urllib3/connectionpool.py", line 703, in urlopen
    httplib_response = self._make_request(
  File "/home/oseloka/pyprojects/maplecourt_py/venv_mc/lib/python3.10/site-packages/urllib3/connectionpool.py", line 386, in _make_request
    self._validate_conn(conn)
  File "/home/oseloka/pyprojects/maplecourt_py/venv_mc/lib/python3.10/site-packages/urllib3/connectionpool.py", line 1042, in _validate_conn
    conn.connect()
  File "/home/oseloka/pyprojects/maplecourt_py/venv_mc/lib/python3.10/site-packages/urllib3/connection.py", line 358, in connect
    self.sock = conn = self._new_conn()
  File "/home/oseloka/pyprojects/maplecourt_py/venv_mc/lib/python3.10/site-packages/urllib3/connection.py", line 186, in _new_conn
    raise NewConnectionError(
urllib3.exceptions.NewConnectionError: <urllib3.connection.HTTPSConnection object at 0x7f7c7e2e4730>: Failed to establish a new connection: [Errno -3] Temporary failure in name resolution

During handling of the above exception, another exception occurred:

Traceback (most recent call last):
  File "/home/oseloka/pyprojects/maplecourt_py/venv_mc/lib/python3.10/site-packages/requests/adapters.py", line 489, in send
    resp = conn.urlopen(
  File "/home/oseloka/pyprojects/maplecourt_py/venv_mc/lib/python3.10/site-packages/urllib3/connectionpool.py", line 787, in urlopen
    retries = retries.increment(
  File "/home/oseloka/pyprojects/maplecourt_py/venv_mc/lib/python3.10/site-packages/urllib3/util/retry.py", line 592, in increment
    raise MaxRetryError(_pool, url, error or ResponseError(cause))
urllib3.exceptions.MaxRetryError: HTTPSConnectionPool(host='oauth2.googleapis.com', port=443): Max retries exceeded with url: /token (Caused by NewConnectionError('<urllib3.connection.HTTPSConnection object at 0x7f7c7e2e4730>: Failed to establish a new connection: [Errno -3] Temporary failure in name resolution'))

During handling of the above exception, another exception occurred:

Traceback (most recent call last):
  File "/home/oseloka/pyprojects/maplecourt_py/venv_mc/lib/python3.10/site-packages/google/auth/transport/requests.py", line 193, in __call__
    response = self.session.request(
  File "/home/oseloka/pyprojects/maplecourt_py/venv_mc/lib/python3.10/site-packages/requests/sessions.py", line 587, in request
    resp = self.send(prep, **send_kwargs)
  File "/home/oseloka/pyprojects/maplecourt_py/venv_mc/lib/python3.10/site-packages/requests/sessions.py", line 701, in send
    r = adapter.send(request, **kwargs)
  File "/home/oseloka/pyprojects/maplecourt_py/venv_mc/lib/python3.10/site-packages/requests/adapters.py", line 565, in send
    raise ConnectionError(e, request=request)
requests.exceptions.ConnectionError: HTTPSConnectionPool(host='oauth2.googleapis.com', port=443): Max retries exceeded with url: /token (Caused by NewConnectionError('<urllib3.connection.HTTPSConnection object at 0x7f7c7e2e4730>: Failed to establish a new connection: [Errno -3] Temporary failure in name resolution'))

The above exception was the direct cause of the following exception:

Traceback (most recent call last):
  File "/home/oseloka/pyprojects/maplecourt_py/MapleCourt_propertyMgt/src/utils/credentials.py", line 41, in get_google_credentials
    creds.refresh(Request())
  File "/home/oseloka/pyprojects/maplecourt_py/venv_mc/lib/python3.10/site-packages/google/oauth2/credentials.py", line 335, in refresh
    ) = reauth.refresh_grant(
  File "/home/oseloka/pyprojects/maplecourt_py/venv_mc/lib/python3.10/site-packages/google/oauth2/reauth.py", line 324, in refresh_grant
    response_status_ok, response_data, retryable_error = _client._token_endpoint_request_no_throw(
  File "/home/oseloka/pyprojects/maplecourt_py/venv_mc/lib/python3.10/site-packages/google/oauth2/_client.py", line 213, in _token_endpoint_request_no_throw
    request_succeeded, response_data, retryable_error = _perform_request()
  File "/home/oseloka/pyprojects/maplecourt_py/venv_mc/lib/python3.10/site-packages/google/oauth2/_client.py", line 189, in _perform_request
    response = request(
  File "/home/oseloka/pyprojects/maplecourt_py/venv_mc/lib/python3.10/site-packages/google/auth/transport/requests.py", line 199, in __call__
    six.raise_from(new_exc, caught_exc)
  File "<string>", line 3, in raise_from
google.auth.exceptions.TransportError: HTTPSConnectionPool(host='oauth2.googleapis.com', port=443): Max retries exceeded with url: /token (Caused by NewConnectionError('<urllib3.connection.HTTPSConnection object at 0x7f7c7e2e4730>: Failed to establish a new connection: [Errno -3] Temporary failure in name resolution'))

During handling of the above exception, another exception occurred:

Traceback (most recent call last):
  File "/usr/lib/python3.10/logging/__init__.py", line 1100, in emit
    msg = self.format(record)
  File "/usr/lib/python3.10/logging/__init__.py", line 943, in format
    return fmt.format(record)
  File "/usr/lib/python3.10/logging/__init__.py", line 678, in format
    record.message = record.getMessage()
  File "/usr/lib/python3.10/logging/__init__.py", line 368, in getMessage
    msg = msg % self.args
TypeError: not all arguments converted during string formatting
Call stack:
  File "/home/oseloka/pyprojects/maplecourt_py/MapleCourt_propertyMgt/src/notifications/rent_notice_email.py", line 146, in <module>
    send_upcoming_rent_email(logger)
  File "/home/oseloka/pyprojects/maplecourt_py/MapleCourt_propertyMgt/src/notifications/rent_notice_email.py", line 118, in send_upcoming_rent_email
    success = send_email("Upcoming Rent Renewal", app_email, email, body, logger_instance)
  File "/home/oseloka/pyprojects/maplecourt_py/MapleCourt_propertyMgt/src/utils/comms.py", line 29, in send_email
    service = get_google_credentials(logger_instance)
  File "/home/oseloka/pyprojects/maplecourt_py/MapleCourt_propertyMgt/src/utils/credentials.py", line 46, in get_google_credentials
    logger_instance.error("Failed to refresh credentials:", e)
Message: 'Failed to refresh credentials:'
Arguments: (TransportError(ConnectionError(MaxRetryError("HTTPSConnectionPool(host='oauth2.googleapis.com', port=443): Max retries exceeded with url: /token (Caused by NewConnectionError('<urllib3.connection.HTTPSConnection object at 0x7f7c7e2e4730>: Failed to establish a new connection: [Errno -3] Temporary failure in name resolution'))"))),)
/home/oseloka/pyprojects/maplecourt_py/MapleCourt_propertyMgt/src/notifications
--- Logging error ---
Traceback (most recent call last):
  File "/home/oseloka/pyprojects/maplecourt_py/venv_mc/lib/python3.10/site-packages/urllib3/connection.py", line 174, in _new_conn
    conn = connection.create_connection(
  File "/home/oseloka/pyprojects/maplecourt_py/venv_mc/lib/python3.10/site-packages/urllib3/util/connection.py", line 72, in create_connection
    for res in socket.getaddrinfo(host, port, family, socket.SOCK_STREAM):
  File "/usr/lib/python3.10/socket.py", line 955, in getaddrinfo
    for res in _socket.getaddrinfo(host, port, family, type, proto, flags):
socket.gaierror: [Errno -3] Temporary failure in name resolution

During handling of the above exception, another exception occurred:

Traceback (most recent call last):
  File "/home/oseloka/pyprojects/maplecourt_py/venv_mc/lib/python3.10/site-packages/urllib3/connectionpool.py", line 703, in urlopen
    httplib_response = self._make_request(
  File "/home/oseloka/pyprojects/maplecourt_py/venv_mc/lib/python3.10/site-packages/urllib3/connectionpool.py", line 386, in _make_request
    self._validate_conn(conn)
  File "/home/oseloka/pyprojects/maplecourt_py/venv_mc/lib/python3.10/site-packages/urllib3/connectionpool.py", line 1042, in _validate_conn
    conn.connect()
  File "/home/oseloka/pyprojects/maplecourt_py/venv_mc/lib/python3.10/site-packages/urllib3/connection.py", line 358, in connect
    self.sock = conn = self._new_conn()
  File "/home/oseloka/pyprojects/maplecourt_py/venv_mc/lib/python3.10/site-packages/urllib3/connection.py", line 186, in _new_conn
    raise NewConnectionError(
urllib3.exceptions.NewConnectionError: <urllib3.connection.HTTPSConnection object at 0x7fa5719ec9d0>: Failed to establish a new connection: [Errno -3] Temporary failure in name resolution

During handling of the above exception, another exception occurred:

Traceback (most recent call last):
  File "/home/oseloka/pyprojects/maplecourt_py/venv_mc/lib/python3.10/site-packages/requests/adapters.py", line 489, in send
    resp = conn.urlopen(
  File "/home/oseloka/pyprojects/maplecourt_py/venv_mc/lib/python3.10/site-packages/urllib3/connectionpool.py", line 787, in urlopen
    retries = retries.increment(
  File "/home/oseloka/pyprojects/maplecourt_py/venv_mc/lib/python3.10/site-packages/urllib3/util/retry.py", line 592, in increment
    raise MaxRetryError(_pool, url, error or ResponseError(cause))
urllib3.exceptions.MaxRetryError: HTTPSConnectionPool(host='oauth2.googleapis.com', port=443): Max retries exceeded with url: /token (Caused by NewConnectionError('<urllib3.connection.HTTPSConnection object at 0x7fa5719ec9d0>: Failed to establish a new connection: [Errno -3] Temporary failure in name resolution'))

During handling of the above exception, another exception occurred:

Traceback (most recent call last):
  File "/home/oseloka/pyprojects/maplecourt_py/venv_mc/lib/python3.10/site-packages/google/auth/transport/requests.py", line 193, in __call__
    response = self.session.request(
  File "/home/oseloka/pyprojects/maplecourt_py/venv_mc/lib/python3.10/site-packages/requests/sessions.py", line 587, in request
    resp = self.send(prep, **send_kwargs)
  File "/home/oseloka/pyprojects/maplecourt_py/venv_mc/lib/python3.10/site-packages/requests/sessions.py", line 701, in send
    r = adapter.send(request, **kwargs)
  File "/home/oseloka/pyprojects/maplecourt_py/venv_mc/lib/python3.10/site-packages/requests/adapters.py", line 565, in send
    raise ConnectionError(e, request=request)
requests.exceptions.ConnectionError: HTTPSConnectionPool(host='oauth2.googleapis.com', port=443): Max retries exceeded with url: /token (Caused by NewConnectionError('<urllib3.connection.HTTPSConnection object at 0x7fa5719ec9d0>: Failed to establish a new connection: [Errno -3] Temporary failure in name resolution'))

The above exception was the direct cause of the following exception:

Traceback (most recent call last):
  File "/home/oseloka/pyprojects/maplecourt_py/MapleCourt_propertyMgt/src/utils/credentials.py", line 41, in get_google_credentials
    creds.refresh(Request())
  File "/home/oseloka/pyprojects/maplecourt_py/venv_mc/lib/python3.10/site-packages/google/oauth2/credentials.py", line 335, in refresh
    ) = reauth.refresh_grant(
  File "/home/oseloka/pyprojects/maplecourt_py/venv_mc/lib/python3.10/site-packages/google/oauth2/reauth.py", line 324, in refresh_grant
    response_status_ok, response_data, retryable_error = _client._token_endpoint_request_no_throw(
  File "/home/oseloka/pyprojects/maplecourt_py/venv_mc/lib/python3.10/site-packages/google/oauth2/_client.py", line 213, in _token_endpoint_request_no_throw
    request_succeeded, response_data, retryable_error = _perform_request()
  File "/home/oseloka/pyprojects/maplecourt_py/venv_mc/lib/python3.10/site-packages/google/oauth2/_client.py", line 189, in _perform_request
    response = request(
  File "/home/oseloka/pyprojects/maplecourt_py/venv_mc/lib/python3.10/site-packages/google/auth/transport/requests.py", line 199, in __call__
    six.raise_from(new_exc, caught_exc)
  File "<string>", line 3, in raise_from
google.auth.exceptions.TransportError: HTTPSConnectionPool(host='oauth2.googleapis.com', port=443): Max retries exceeded with url: /token (Caused by NewConnectionError('<urllib3.connection.HTTPSConnection object at 0x7fa5719ec9d0>: Failed to establish a new connection: [Errno -3] Temporary failure in name resolution'))

During handling of the above exception, another exception occurred:

Traceback (most recent call last):
  File "/usr/lib/python3.10/logging/__init__.py", line 1100, in emit
    msg = self.format(record)
  File "/usr/lib/python3.10/logging/__init__.py", line 943, in format
    return fmt.format(record)
  File "/usr/lib/python3.10/logging/__init__.py", line 678, in format
    record.message = record.getMessage()
  File "/usr/lib/python3.10/logging/__init__.py", line 368, in getMessage
    msg = msg % self.args
TypeError: not all arguments converted during string formatting
Call stack:
  File "/home/oseloka/pyprojects/maplecourt_py/MapleCourt_propertyMgt/src/notifications/rent_notice_email.py", line 146, in <module>
    send_upcoming_rent_email(logger)
  File "/home/oseloka/pyprojects/maplecourt_py/MapleCourt_propertyMgt/src/notifications/rent_notice_email.py", line 118, in send_upcoming_rent_email
    success = send_email("Upcoming Rent Renewal", app_email, email, body, logger_instance)
  File "/home/oseloka/pyprojects/maplecourt_py/MapleCourt_propertyMgt/src/utils/comms.py", line 29, in send_email
    service = get_google_credentials(logger_instance)
  File "/home/oseloka/pyprojects/maplecourt_py/MapleCourt_propertyMgt/src/utils/credentials.py", line 46, in get_google_credentials
    logger_instance.error("Failed to refresh credentials:", e)
Message: 'Failed to refresh credentials:'
Arguments: (TransportError(ConnectionError(MaxRetryError("HTTPSConnectionPool(host='oauth2.googleapis.com', port=443): Max retries exceeded with url: /token (Caused by NewConnectionError('<urllib3.connection.HTTPSConnection object at 0x7fa5719ec9d0>: Failed to establish a new connection: [Errno -3] Temporary failure in name resolution'))"))),)
/home/oseloka/pyprojects/maplecourt_py/MapleCourt_propertyMgt/src/notifications
--- Logging error ---
Traceback (most recent call last):
  File "/home/oseloka/pyprojects/maplecourt_py/venv_mc/lib/python3.10/site-packages/urllib3/connection.py", line 174, in _new_conn
    conn = connection.create_connection(
  File "/home/oseloka/pyprojects/maplecourt_py/venv_mc/lib/python3.10/site-packages/urllib3/util/connection.py", line 72, in create_connection
    for res in socket.getaddrinfo(host, port, family, socket.SOCK_STREAM):
  File "/usr/lib/python3.10/socket.py", line 955, in getaddrinfo
    for res in _socket.getaddrinfo(host, port, family, type, proto, flags):
socket.gaierror: [Errno -3] Temporary failure in name resolution

During handling of the above exception, another exception occurred:

Traceback (most recent call last):
  File "/home/oseloka/pyprojects/maplecourt_py/venv_mc/lib/python3.10/site-packages/urllib3/connectionpool.py", line 703, in urlopen
    httplib_response = self._make_request(
  File "/home/oseloka/pyprojects/maplecourt_py/venv_mc/lib/python3.10/site-packages/urllib3/connectionpool.py", line 386, in _make_request
    self._validate_conn(conn)
  File "/home/oseloka/pyprojects/maplecourt_py/venv_mc/lib/python3.10/site-packages/urllib3/connectionpool.py", line 1042, in _validate_conn
    conn.connect()
  File "/home/oseloka/pyprojects/maplecourt_py/venv_mc/lib/python3.10/site-packages/urllib3/connection.py", line 358, in connect
    self.sock = conn = self._new_conn()
  File "/home/oseloka/pyprojects/maplecourt_py/venv_mc/lib/python3.10/site-packages/urllib3/connection.py", line 186, in _new_conn
    raise NewConnectionError(
urllib3.exceptions.NewConnectionError: <urllib3.connection.HTTPSConnection object at 0x7fd939de45e0>: Failed to establish a new connection: [Errno -3] Temporary failure in name resolution

During handling of the above exception, another exception occurred:

Traceback (most recent call last):
  File "/home/oseloka/pyprojects/maplecourt_py/venv_mc/lib/python3.10/site-packages/requests/adapters.py", line 489, in send
    resp = conn.urlopen(
  File "/home/oseloka/pyprojects/maplecourt_py/venv_mc/lib/python3.10/site-packages/urllib3/connectionpool.py", line 787, in urlopen
    retries = retries.increment(
  File "/home/oseloka/pyprojects/maplecourt_py/venv_mc/lib/python3.10/site-packages/urllib3/util/retry.py", line 592, in increment
    raise MaxRetryError(_pool, url, error or ResponseError(cause))
urllib3.exceptions.MaxRetryError: HTTPSConnectionPool(host='oauth2.googleapis.com', port=443): Max retries exceeded with url: /token (Caused by NewConnectionError('<urllib3.connection.HTTPSConnection object at 0x7fd939de45e0>: Failed to establish a new connection: [Errno -3] Temporary failure in name resolution'))

During handling of the above exception, another exception occurred:

Traceback (most recent call last):
  File "/home/oseloka/pyprojects/maplecourt_py/venv_mc/lib/python3.10/site-packages/google/auth/transport/requests.py", line 193, in __call__
    response = self.session.request(
  File "/home/oseloka/pyprojects/maplecourt_py/venv_mc/lib/python3.10/site-packages/requests/sessions.py", line 587, in request
    resp = self.send(prep, **send_kwargs)
  File "/home/oseloka/pyprojects/maplecourt_py/venv_mc/lib/python3.10/site-packages/requests/sessions.py", line 701, in send
    r = adapter.send(request, **kwargs)
  File "/home/oseloka/pyprojects/maplecourt_py/venv_mc/lib/python3.10/site-packages/requests/adapters.py", line 565, in send
    raise ConnectionError(e, request=request)
requests.exceptions.ConnectionError: HTTPSConnectionPool(host='oauth2.googleapis.com', port=443): Max retries exceeded with url: /token (Caused by NewConnectionError('<urllib3.connection.HTTPSConnection object at 0x7fd939de45e0>: Failed to establish a new connection: [Errno -3] Temporary failure in name resolution'))

The above exception was the direct cause of the following exception:

Traceback (most recent call last):
  File "/home/oseloka/pyprojects/maplecourt_py/MapleCourt_propertyMgt/src/utils/credentials.py", line 41, in get_google_credentials
    creds.refresh(Request())
  File "/home/oseloka/pyprojects/maplecourt_py/venv_mc/lib/python3.10/site-packages/google/oauth2/credentials.py", line 335, in refresh
    ) = reauth.refresh_grant(
  File "/home/oseloka/pyprojects/maplecourt_py/venv_mc/lib/python3.10/site-packages/google/oauth2/reauth.py", line 324, in refresh_grant
    response_status_ok, response_data, retryable_error = _client._token_endpoint_request_no_throw(
  File "/home/oseloka/pyprojects/maplecourt_py/venv_mc/lib/python3.10/site-packages/google/oauth2/_client.py", line 213, in _token_endpoint_request_no_throw
    request_succeeded, response_data, retryable_error = _perform_request()
  File "/home/oseloka/pyprojects/maplecourt_py/venv_mc/lib/python3.10/site-packages/google/oauth2/_client.py", line 189, in _perform_request
    response = request(
  File "/home/oseloka/pyprojects/maplecourt_py/venv_mc/lib/python3.10/site-packages/google/auth/transport/requests.py", line 199, in __call__
    six.raise_from(new_exc, caught_exc)
  File "<string>", line 3, in raise_from
google.auth.exceptions.TransportError: HTTPSConnectionPool(host='oauth2.googleapis.com', port=443): Max retries exceeded with url: /token (Caused by NewConnectionError('<urllib3.connection.HTTPSConnection object at 0x7fd939de45e0>: Failed to establish a new connection: [Errno -3] Temporary failure in name resolution'))

During handling of the above exception, another exception occurred:

Traceback (most recent call last):
  File "/usr/lib/python3.10/logging/__init__.py", line 1100, in emit
    msg = self.format(record)
  File "/usr/lib/python3.10/logging/__init__.py", line 943, in format
    return fmt.format(record)
  File "/usr/lib/python3.10/logging/__init__.py", line 678, in format
    record.message = record.getMessage()
  File "/usr/lib/python3.10/logging/__init__.py", line 368, in getMessage
    msg = msg % self.args
TypeError: not all arguments converted during string formatting
Call stack:
  File "/home/oseloka/pyprojects/maplecourt_py/MapleCourt_propertyMgt/src/notifications/rent_notice_email.py", line 146, in <module>
    send_upcoming_rent_email(logger)
  File "/home/oseloka/pyprojects/maplecourt_py/MapleCourt_propertyMgt/src/notifications/rent_notice_email.py", line 118, in send_upcoming_rent_email
    success = send_email("Upcoming Rent Renewal", app_email, email, body, logger_instance)
  File "/home/oseloka/pyprojects/maplecourt_py/MapleCourt_propertyMgt/src/utils/comms.py", line 29, in send_email
    service = get_google_credentials(logger_instance)
  File "/home/oseloka/pyprojects/maplecourt_py/MapleCourt_propertyMgt/src/utils/credentials.py", line 46, in get_google_credentials
    logger_instance.error("Failed to refresh credentials:", e)
Message: 'Failed to refresh credentials:'
Arguments: (TransportError(ConnectionError(MaxRetryError("HTTPSConnectionPool(host='oauth2.googleapis.com', port=443): Max retries exceeded with url: /token (Caused by NewConnectionError('<urllib3.connection.HTTPSConnection object at 0x7fd939de45e0>: Failed to establish a new connection: [Errno -3] Temporary failure in name resolution'))"))),)
